Workbook
Name a_sales: Sumif_sheets!$B$2
Name b_sales: Sumif_sheets!$B$3
Name c_sales: Sumif_sheets!$B$4
Name d_sales: Sumif_sheets!$B$5
Name e_sales: Sumif_sheets!$B$6
Name t_sales: Sumif_sheets!$B$7

Sheet Raw_Data
A1: Order No | B1: Order Date | C1: Customer Name | D1: Address | E1: City | F1: State | G1: Customer Type | H1: Account Manager | I1: Order Priority | J1: Product Name | K1: Product Category | L1: Product Container | M1: Ship Mode | N1: Ship Date | O1: Cost Price | P1: Retail Price | Q1: Profit Margin | R1: Order Quantity | S1: Sub Total | T1: Discount % | U1: Discount $ | V1: Order Total | W1: Shipping Cost | X1: Total
A2: 4293-1 | B2: 41884 | C2: Vivek Sundaresam | D2: 152 Bunnerong Road,Eastgardens | E2: Sydney | F2: NSW | G2: Small Business | H2: Tina Carlton | I2: Critical | J2: UGen Ultra Professional Cordless Optical Suite | K2: Office Supplies | L2: Small Box | M2: Regular Air | N2: 41886 | O2: $156.50 | P2: $300.97 | Q2: $144.47 | R2: 23 | S2: $4,533.52 | T2: 0.02 | U2: $194.83 | V2: $4,757.22 | W2: $7.18 | X2: $4,291.55
A3: 5001-1 | B3: 42301 | C3: Shahid Hopkins | D3: 438 Victoria Avenue,Chatswood | E3: Sydney | F3: NSW | G3: Corporate | H3: Natasha Song | I3: Medium | J3: Bagged Rubber Bands | K3: Office Supplies | L3: Small Pack | M3: Regular Air | N3: 42303 | O3: $0.24 | P3: $1.26 | Q3: $1.02 | R3: 8 | S3: $45.20 | T3: 0.03 | U3: $0.00 | V3: $45.90 | W3: $0.70 | X3: $46.91
A4: 5004-1 | B4: 41711 | C4: Dennis Pardue | D4: 412 Brunswick St,Fitzroy | E4: Melbourne | F4: VIC | G4: Consumer | H4: Connor Betts | I4: Not Specified | J4: TechSavi Cordless Navigator Duo | K4: Office Supplies | L4: Small Box | M4: Regular Air | N4: 41711 | O4: $42.11 | P4: $80.98 | Q4: $38.87 | R4: 45 | S4: $873.32 | T4: 0.04 | U4: $72.23 | V4: $837.57 | W4: $7.18 | X4: $82.58
A5: 5009-1 | B5: 41323 | C5: Sean Wendt | D5: 145 Ramsay St,Haberfield | E5: Sydney | F5: NSW | G5: Small Business | H5: Phoebe Gour | I5: Critical | J5: Artisan Printable Repositionable Plastic Tabs | K5: Office Supplies | L5: Wrap Bag | M5: Regular Air | N5: 41325 | O5: $5.33 | P5: $8.60 | Q5: $3.27 | R5: 16 | S5: $73.52 | T5: 0.01 | U5: $4.35 | V5: $740.67 | W5: $6.19 | X5: $730.92
A6: 5010-1 | B6: 41895 | C6: Christina Vanderzanden | D6: 188 Pitt Street,Sydney | E6: Sydney | F6: NSW | G6: Small Business | H6: Tina Carlton | I6: Not Specified | J6: Pizazz Drawing Pencil Set | K6: Office Supplies | L6: Wrap Bag | M6: Express Air | N6: 41899 | O6: $1.53 | P6: $2.78 | Q6: $1.25 | R6: 49 | S6: $138.46 | T6: 0.07 | U6: $5.95 | V6: $123.77 | W6: $1.34 | X6: $125.97
A7: 5011-1 | B7: 41602 | C7: Patrick OBrill | D7: 53 Riley Street,Woolloomooloo | E7: Sydney | F7: NSW | G7: Home Office | H7: Tina Carlton | I7: Not Specified | J7: Alto Parchment Paper, Assorted Colors | K7: Office Supplies | L7: Wrap Bag | M7: Regular Air | N7: 41604 | O7: $4.59 | P7: $7.28 | Q7: $2.69 | R7: 45 | S7: $197.36 | T7: 0.08 | U7: $12.98 | V7: $183.58 | W7: $11.15 | X7: $189.43
A8: 5012-1 | B8: 41889 | C8: Eugene Moren | D8: 85-113 Dunning Ave,Rosebery | E8: Sydney | F8: NSW | G8: Consumer | H8: Mihael Khan | I8: Not Specified | J8: Smiths Metal Binder Clips | K8: Office Supplies | L8: Small Box | M8: Regular Air | N8: 41889 | O8: $1.60 | P8: $2.62 | Q8: $1.02 | R8: 45 | S8: $65.50 | T8: 0.04 | U8: $5.90 | V8: $59.62 | W8: $0.80 | X8: $60.45
A9: 5012-1 | B9: 42032 | C9: Phillip Flathmann | D9: Macquarie Centre Cnr Herring Road & Waterloo Road,Macquarie Park | E9: Sydney | F9: NSW | G9: Home Office | H9: Nicholas Fernandes | I9: Medium | J9: Smiths Metal Binder Clips | K9: Technology | L9: Small Box | M9: Regular Air | N9: 42033 | O9: $1.60 | P9: $2.62 | Q9: $1.02 | R9: 34 | S9: $24.92 | T9: 0.02 | U9: $2.49 | V9: $22.43 | W9: $0.80 | X9: $27.43
A10: 5014-1 | B10: 41798 | C10: John Lee | D10: 180 High Street,Windsor | E10: Melbourne | F10: VIC | G10: Home Office | H10: Connor Betts | I10: Not Specified | J10: Artisan Hole Reinforcements | K10: Office Supplies | L10: Wrap Bag | M10: Regular Air | N10: 41800 | O10: $3.99 | P10: $6.23 | Q10: $2.24 | R10: 25 | S10: $194.36 | T10: 0.1 | U10: $15.93 | V10: $178.12 | W10: $6.97 | X10: $189.45
A11: 5015-1 | B11: 41914 | C11: Ritsa Hightower | D11: 1/160 Anzac Parade,Kensington | E11: Sydney | F11: NSW | G11: Corporate | H11: Natasha Song | I11: Critical | J11: UGen Ultra Professional Cordless Optical Suite | K11: Office Supplies | L11: Small Box | M11: Regular Air | N11: 41916 | O11: $156.50 | P11: $300.97 | Q11: $144.47 | R11: 42 | S11: $1,079.62 | T11: 0.04 | U11: $30.83 | V11: $1,753.33 | W11: $7.18 | X11: $1,705.42
A12: 5015-1 | B12: 41730 | C12: Anne Pryor | D12: 1-2/299 Sussex St,Sydney | E12: Sydney | F12: NSW | G12: Corporate | H12: Aanya Zhang | I12: Medium | J12: UGen Ultra Professional Cordless Optical Suite | K12: Office Supplies | L12: Wrap Bag | M12: Express Air | N12: 41731 | O12: $156.50 | P12: $300.97 | Q12: $144.47 | R12: 3 | S12: $1,602.02 | T12: 0.1 | U12: $144.41 | V12: $1,513.83 | W12: $7.18 | X12: $1,533.62
A13: 5016-1 | B13: 41316 | C13: Alex Russell | D13: 99 Lygon Street,East Brunswick | E13: Melbourne | F13: VIC | G13: Consumer | H13: Connor Betts | I13: Low | J13: DrawIt Pizazz Watercolor Pencils, 10-Color Set with Brush | K13: Office Supplies | L13: Wrap Bag | M13: Regular Air | N13: 41317 | O13: $2.39 | P13: $4.26 | Q13: $1.87 | R13: 18 | S13: $123.54 | T13: 0.06 | U13: $3.71 | V13: $119.83 | W13: $1.20 | X13: $121.03
... A1412: 5428-1 | B1412: 41695 | C1412: Rick Hansen | D1412: Macquarie Centre Cnr Herring Road & Waterloo Road,Macquarie Park | E1412: Sydney | F1412: NSW | G1412: Consumer | H1412: Nicholas Fernandes | I1412: High | J1412: Creator Colored Pencils | K1412: Office Supplies | L1412: Wrap Bag | M1412: Regular Air | N1412: 41696 | O1412: $1.57 | P1412: $3.28 | Q1412: $1.71 | R1412: 29 | S1412: $85.28 | T1412: 0.03 | U1412: $6.82 | V1412: $78.46 | W1412: $0.98 | X1412: $79.44
A1413: 5428-1 | B1413: 41695 | C1413: Jhrip Luxen | D1413: 4A Lyons St,Strathfield | E1413: Sydney | F1413: NSW | G1413: Home Office | H1413: Tina Carlton | I1413: High | J1413: Creator Colored Pencils | K1413: Furniture | L1413: Large Box | M1413: Regular Air | N1413: 41696 | O1413: $1.57 | P1413: $3.28 | Q1413: $1.71 | S1413: $85.28 | T1413: 0.04 | U1413: $6.82 | V1413: $78.46 | W1413: $0.98 | X1413: $79.44
A1414: 5429-1 | B1414: 41363 | C1414: Justin Knight | D1414: Macquarie Centre Cnr Herring Road & Waterloo Road,Macquarie Park | E1414: Sydney | F1414: NSW | G1414: Small Business | H1414: Nicholas Fernandes | I1414: Not Specified | J1414: Artisan Binder Labels | K1414: Office Supplies | L1414: Small Box | M1414: Regular Air | N1414: 41364 | O1414: $2.45 | P1414: $3.89 | Q1414: $1.44 | R1414: 8 | S1414: $52.93 | T1414: 0.07 | U1414: $0.17 | V1414: $59.33 | W1414: $7.01 | X1414: $60.68
A1415: 5429-1 | B1415: 41798 | C1415: John Lee | D1415: 180 High Street,Windsor | E1415: Melbourne | F1415: VIC | G1415: Small Business | H1415: Connor Betts | I1415: High | J1415: Bagged Rubber Bands | K1415: Office Supplies | L1415: Small Box | M1415: Express Air | N1415: 41800 | O1415: $0.24 | P1415: $1.26 | Q1415: $1.02 | R1415: 27 | S1415: $90.08 | T1415: 0 | U1415: $5.44 | V1415: $80.62 | W1415: $0.70 | X1415: $83.57
A1416: 5429-1 | B1416: 41579 | C1416: Kristina Nunn | D1416: 22 Civic Rd,Auburn | E1416: Sydney | F1416: NSW | G1416: Small Business | H1416: Mihael Khan | I1416: Low | J1416: Artisan 48 Labels | K1416: Technology | L1416: Jumbo Drum | M1416: Delivery Truck | N1416: 41580 | O1416: $3.84 | P1416: $6.30 | Q1416: $2.46 | R1416: 47 | S1416: $136.04 | T1416: 0.02 | U1416: $5.05 | V1416: $121.83 | W1416: $0.50 | X1416: $132.95
A1417: 5429-1 | B1417: 41425 | C1417: Raymond Fair | D1417: 188 Pitt Street,Sydney | E1417: Sydney | F1417: NSW | G1417: Small Business | H1417: Tina Carlton | I1417: Critical | J1417: Apex Box Cutter Scissors | K1417: Office Supplies | L1417: Small Box | M1417: Express Air | N1417: 41427 | O1417: $4.19 | P1417: $10.23 | Q1417: $6.04 | R1417: 42 | S1417: $465.56 | T1417: 0.07 | U1417: $18.56 | V1417: $422.10 | W1417: $4.68 | X1417: $423.29
A1418: 5429-1 | B1418: 41774 | C1418: Eric Barreto | D1418: 359 Crown Street,Surry Hills | E1418: Sydney | F1418: NSW | G1418: Corporate | H1418: Phoebe Gour | I1418: High | J1418: Lumi Crayons | K1418: Furniture | L1418: Small Pack | M1418: Regular Air | N1418: 41775 | O1418: $5.22 | P1418: $9.85 | Q1418: $4.63 | R1418: 1 | S1418: $89.50 | T1418: 0.1 | U1418: $0.00 | V1418: $89.50 | W1418: $4.82 | X1418: $94.97
A1419: 5429-1 | B1419: 41425 | C1419: Raymond Fair | D1419: 188 Pitt Street,Sydney | E1419: Sydney | F1419: NSW | G1419: Home Office | H1419: Tina Carlton | I1419: Not Specified | J1419: EcoTones Memo Sheets | K1419: Office Supplies | L1419: Wrap Bag | M1419: Regular Air | N1419: 41427 | O1419: $2.52 | P1419: $4.00 | Q1419: $1.48 | R1419: 41 | S1419: $125.00 | T1419: 0.07 | U1419: $12.54 | V1419: $121.74 | W1419: $1.30 | X1419: $122.74
A1420: 5429-1 | B1420: 42024 | C1420: Saphhira Shifley | D1420: Westfield Miranda, 600 Kingsway,Miranda | E1420: Sydney | F1420: NSW | G1420: Corporate | H1420: Preston Senome | I1420: Critical | J1420: Artisan 479 Labels | K1420: Office Supplies | L1420: Small Box | M1420: Regular Air | N1420: 42025 | O1420: $1.59 | P1420: $2.61 | Q1420: $1.02 | R1420: 8 | S1420: $127.24 | T1420: 0.04 | U1420: $11.12 | V1420: $127.76 | W1420: $0.50 | X1420: $122.16
A1421: 5429-1 | B1421: 41572 | C1421: Dan Campbell | D1421: 1/173-179 Bronte Rd,Waverley | E1421: Sydney | F1421: NSW | G1421: Corporate | H1421: Leighton Forrest | I1421: Medium | J1421: Artisan 481 Labels | K1421: Office Supplies | L1421: Wrap Bag | M1421: Regular Air | N1421: 41574 | O1421: $1.94 | P1421: $3.08 | Q1421: $1.14 | R1421: 20 | S1421: $452.00 | T1421: 0.06 | U1421: $45.28 | V1421: $412.00 | W1421: $0.99 | X1421: $413.99
A1422: 5430-1 | B1422: 41695 | C1422: Gary Hwang | D1422: 60 York St,Sydney | E1422: Sydney | F1422: NSW | G1422: Corporate | H1422: Charlie Bui | I1422: Medium | J1422: Steady Major Accent Highlighters | K1422: Office Supplies | L1422: Small Box | M1422: Regular Air | N1422: 41697 | O1422: $3.75 | P1422: $7.08 | Q1422: $3.33 | R1422: 27 | S1422: $220.44 | T1422: 0.04 | U1422: $6.61 | V1422: $213.83 | W1422: $2.35 | X1422: $215.33
A1423: 5430-1 | B1423: 42342 | C1423: Cari Schnelling | D1423: 273 George Street,Sydney | E1423: Sydney | F1423: NSW | G1423: Home Office | H1423: Leighton Forrest | I1423: Critical | J1423: Assorted Color Push Pins | K1423: Office Supplies | L1423: Wrap Bag | M1423: Regular Air | N1423: 42341 | O1423: $0.87 | P1423: $1.81 | Q1423: $0.94 | R1423: 36 | S1423: $80.64 | T1423: 0.01 | U1423: $8.06 | V1423: $72.58 | W1423: $0.75 | X1423: $73.58
A1424: 5430-1 | B1424: 41695 | C1424: Patrick Junes | D1424: Hoyts Entertainment Quarter 122 Lang Road,Moore Parra | E1424: Sydney | F1424: NSW | G1424: Home Office | H1424: Tina Carlton | I1424: Not Specified | J1424: Steady Major Accent Highlighters | K1424: Office Supplies | L1424: Small Box | M1424: Regular Air | N1424: 41697 | O1424: $3.75 | P1424: $7.08 | Q1424: $3.33 | R1424: 44 | S1424: $220.44 | T1424: 0.02 | U1424: $6.61 | V1424: $213.83 | W1424: $2.35 | X1424: $215.33
A1425: 5430-1 | B1425: 41695 | C1425: Gary Hwang | D1425: 60 York St,Sydney | E1425: Sydney | F1425: NSW | G1425: Consumer | H1425: Charlie Bui | I1425: Critical | J1425: Security-Tint Envelopes | K1425: Office Supplies | L1425: Small Box | M1425: Regular Air | N1425: 41697 | O1425: $4.89 | P1425: $7.64 | Q1425: $2.75 | R1425: 34 | S1425: $220.44 | T1425: 0.03 | U1425: $6.61 | V1425: $213.83 | W1425: $1.39 | X1425: $215.33
... A4355: 6384-1 | B4355: 42441 | C4355: Andrew Allen | D4355: 2/797 Botany Rd,Rosebery | E4355: Sydney | F4355: NSW | G4355: Small Business | H4355: Samantha Chairs | I4355: Low | J4355: HFX LaserJet 3310 Copier | K4355: Office Supplies | L4355: Small Box | M4355: Regular Air | N4355: 42446 | O4355: $377.99 | P4355: $599.99 | Q4355: $222.00 | R4355: 38 | S4355: $9,299.84 | T4355: 0.03 | U4355: $0.00 | V4355: $9,599.84 | W4355: $24.49 | X4355: $9,624.33
A4356: 6384-1 | B4356: 42487 | C4356: Patt Bawkins | E4356: Sydney | F4356: NSW | G4356: Small Business | H4356: Tina Carlton | I4356: High | J4356: HFX LaserJet 3310 Copier | K4356: Office Supplies | L4356: Small Box | M4356: Regular Air | N4356: 42489 | O4356: $377.99 | P4356: $599.99 | Q4356: $222.00 | R4356: 47 | S4356: $9,599.84 | T4356: 0 | U4356: $0.00 | V4356: $9,599.84 | W4356: $24.49 | X4356: $9,624.33
A4357: 6384-1 | B4357: 42597 | C4357: Dave Hallsten | D4357: 1 John St,Waterloo | E4357: Sydney | F4357: NSW | G4357: Consumer | H4357: Charlie Bui | I4357: High | J4357: HFX LaserJet 3310 Copier | K4357: Office Supplies | L4357: Wrap Bag | M4357: Regular Air | N4357: 42602 | O4357: $377.99 | P4357: $599.99 | Q4357: $222.00 | R4357: 33 | S4357: $9,799.84 | T4357: 0 | U4357: $0.00 | V4357: $9,599.84 | W4357: $24.49 | X4357: $9,624.33
A4358: 6384-1 | B4358: 42593 | C4358: Sung Shariari | D4358: 6/15 Cross Street,Double Bay | E4358: Sydney | F4358: NSW | G4358: Consumer | H4358: Leighton Forrest | I4358: High | J4358: HFX LaserJet 3310 Copier | K4358: Technology | L4358: Small Box | M4358: Regular Air | N4358: 42595 | O4358: $377.99 | P4358: $599.99 | Q4358: $222.00 | R4358: 40 | S4358: $9,599.84 | T4358: 0.03 | U4358: $0.00 | V4358: $9,599.84 | W4358: $24.49 | X4358: $9,624.33
A4359: 6384-1 | B4359: 42606 | C4359: Quincy Jones | D4359: Shop 3/144 Waterloo Road,Greenacre | E4359: Sydney | F4359: NSW | G4359: Corporate | H4359: Samantha Chairs | I4359: Critical | J4359: HFX LaserJet 3310 Copier | K4359: Office Supplies | L4359: Small Box | M4359: Regular Air | N4359: 42606 | O4359: $377.99 | P4359: $599.99 | Q4359: $222.00 | R4359: 39 | S4359: $9,599.84 | T4359: 0.08 | U4359: $0.00 | V4359: $9,599.84 | W4359: $24.49 | X4359: $9,624.33
A4360: 6384-1 | B4360: 42606 | C4360: Jasper Cacioppo | D4360: 24 Addison Rd,Marrickville | E4360: Sydney | F4360: NSW | G4360: Small Business | H4360: Radhya Staples | I4360: Critical | J4360: HFX LaserJet 3310 Copier | K4360: Technology | L4360: Small Box | M4360: Regular Air | N4360: 42615 | O4360: $377.99 | P4360: $599.99 | Q4360: $222.00 | R4360: 15 | S4360: $9,599.84 | T4360: 0.08 | U4360: $0.00 | V4360: $9,599.84 | W4360: $24.49 | X4360: $9,624.33
A4361: 6384-1 | B4361: 42478 | C4361: Don Weiss | D4361: 79 Elliott St,Balmain | E4361: Sydney | F4361: NSW | G4361: Home Office | H4361: Aanya Zhang | I4361: High | J4361: UGen Ultra Professional Cordless Optical Suite | K4361: Office Supplies | L4361: Wrap Bag | M4361: Regular Air | N4361: 42479 | O4361: $156.50 | P4361: $300.97 | Q4361: $144.47 | R4361: 16 | S4361: $1,016.52 | T4361: 0.1 | U4361: $0.00 | V4361: $1,088.64 | W4361: $7.18 | X4361: $1,012.70
A4362: 6384-1 | B4362: 42512 | C4362: Eva Jacobs | D4362: Westfield 1 Anderson St,Chatswood | E4362: Sydney | F4362: NSW | G4362: Small Business | H4362: Nicholas Fernandes | I4362: Critical | J4362: Artisan 479 Labels | K4362: Office Supplies | L4362: Small Box | M4362: Regular Air | N4362: 42513 | O4362: $1.59 | P4362: $2.61 | Q4362: $1.02 | R4362: 6 | S4362: $31.36 | T4362: 0.03 | U4362: $3.52 | V4362: $30.66 | W4362: $0.50 | X4362: $31.06
A4363: 6385-1 | B4363: 42606 | C4363: Jasper Cacioppo | D4363: 24 Addison Rd,Marrickville | E4363: Sydney | F4363: NSW | G4363: Home Office | H4363: Radhya Staples | I4363: Not Specified | J4363: EcoTones Memo Sheets | K4363: Office Supplies | L4363: Wrap Bag | M4363: Regular Air | N4363: 42615 | O4363: $2.52 | P4363: $4.00 | Q4363: $1.48 | R4363: 11 | S4363: $97.56 | T4363: 0.07 | U4363: $0.00 | V4363: $93.66 | W4363: $1.30 | X4363: $96.33
A4364: 6385-1 | B4364: 42511 | C4364: John Lucas | D4364: 188 Pitt Street,Sydney | E4364: Sydney | F4364: NSW | G4364: Corporate | H4364: Tina Carlton | I4364: Critical | J4364: Artisan 479 Labels | K4364: Office Supplies | L4364: Small Box | M4364: Regular Air | N4364: 42512 | O4364: $1.59 | P4364: $2.61 | Q4364: $1.02 | R4364: 8 | S4364: $22.32 | T4364: 0.02 | U4364: $2.29 | V4364: $21.05 | W4364: $0.50 | X4364: $22.25
A4365: 6385-1 | B4365: 42769 | C4365: Bor Prostek | D4365: 120 Hardware St,Melbourne | E4365: Melbourne | F4365: VIC | G4365: Home Office | H4365: Connor Betts | I4365: Not Specified | J4365: Office Shears by Apex | K4365: Office Supplies | L4365: Wrap Bag | M4365: Regular Air | N4365: 42771 | O4365: $0.94 | P4365: $2.08 | Q4365: $1.14 | R4365: 1 | S4365: $89.34 | T4365: 0.1 | U4365: $3.47 | V4365: $86.88 | W4365: $2.56 | X4365: $88.38
A4366: 6385-1 | B4366: 42483 | C4366: Thomas Thornton | D4366: 222 Barkly St,St Kilda | E4366: Melbourne | F4366: VIC | G4366: Corporate | H4366: Yvette Biti | I4366: Critical | J4366: Artisan 474 Labels | K4366: Office Supplies | L4366: Wrap Bag | M4366: Regular Air | N4366: 42484 | O4366: $1.84 | P4366: $2.88 | Q4366: $1.04 | R4366: 36 | S4366: $81.94 | T4366: 0 | U4366: $0.00 | V4366: $82.46 | W4366: $0.99 | X4366: $88.14
A4367: 6385-1 | B4367: 42626 | C4367: Christina Vanderzanden | D4367: 188 Pitt Street,Sydney | E4367: Sydney | F4367: NSW | G4367: Corporate | H4367: Tina Carlton | I4367: Critical | J4367: Pizazz Drawing Pencil Set | K4367: Office Supplies | L4367: Wrap Bag | M4367: Regular Air | N4367: 42633 | O4367: $1.53 | P4367: $2.78 | Q4367: $1.25 | R4367: 11 | S4367: $63.36 | T4367: 0.07 | U4367: $2.76 | V4367: $62.98 | W4367: $1.34 | X4367: $66.28
...

Sheet Retail_insight
A1: Order No | B1: Order Date | C1: Customer Name | D1: Address | E1: City | F1: State | G1: Customer Type | H1: Account Manager | I1: Order Priority | J1: Product Name | K1: Product Category | L1: Product Container | M1: Ship Mode | N1: Ship Date | O1: Cost Price | P1: Retail Price | Q1: Profit Margin | R1: Order Quantity | S1: Sub Total | T1: Discount % | U1: Discount $ | V1: Order Total | W1: Shipping Cost | X1: Total | Y1: Order Total Number | Z1: Total Number | AA1: Difference | AB1: Shipping Cost Number | AC1: Discount $ Number | AD1: Retail Price Number | AE1: Sales (Customer Shipping cost) | AF1: Sales (Without Shipping Cost) | AG1: Sales( Company Shipping Cost) | AH1: Sales without discount | AI1: Year
A2: 4293-1 | B2: 41884 | C2: Vivek Sundaresam | D2: 152 Bunnerong Road,Eastgardens | E2: Sydney | F2: NSW | G2: Small Business | H2: Tina Carlton | I2: Critical | J2: UGen Ultra Professional Cordless Optical Suite | K2: Office Supplies | L2: Small Box | M2: Regular Air | N2: 41886 | O2: $156.50 | P2: $300.97 | Q2: $144.47 | R2: 23 | S2: $4,533.52 | T2: 0.02 | U2: $194.83 | V2: $4,757.22 | W2: $7.18 | X2: $4,291.55 | Y2: =VALUE(SUBSTITUTE(Table1[[#This Row],[Order Total]],"$","")) -> 4757.22 | Z2: =VALUE(SUBSTITUTE(Table1[[#This Row],[Total]],"$","")) -> 4291.55 | AA2: =Table1[[#This Row],[Order Total Number]]-Table1[[#This Row],[Total Number]] -> 465.67 | AB2: =VALUE(SUBSTITUTE(Table1[[#This Row],[Shipping Cost]],"$","")) -> 7.18 | AC2: =VALUE(SUBSTITUTE(Table1[[#This Row],[Discount $]],"$","")) -> 194.83 | AD2: =VALUE(SUBSTITUTE(Table1[[#This Row],[Retail Price]],"$","")) -> 300.97 | AE2: =(Table1[[#This Row],[Retail Price Number]]*Table1[[#This Row],[Order Quantity]])-Table1[[#This Row],[Discount $ Number]]+Table1[[#This Row],[Shipping Cost Number]] -> 6734.66 | AF2: =Table1[[#This Row],[Retail Price Number]]*Table1[[#This Row],[Order Quantity]]-Table1[[#This Row],[Discount $ Number]] -> 6727.48 | AG2: =(Table1[[#This Row],[Retail Price Number]]*Table1[[#This Row],[Order Quantity]])-Table1[[#This Row],[Discount $ Number]]-Table1[[#This Row],[Shipping Cost Number]] -> 6720.3 | AH2: =Table1[[#This Row],[Retail Price Number]]*Table1[[#This Row],[Order Quantity]] -> 6922.31 | AI2: =YEAR(Table1[[#This Row],[Order Date]]) -> 2014
A3: 5001-1 | B3: 42301 | C3: Shahid Hopkins | D3: 438 Victoria Avenue,Chatswood | E3: Sydney | F3: NSW | G3: Corporate | H3: Natasha Song | I3: Medium | J3: Bagged Rubber Bands | K3: Office Supplies | L3: Small Pack | M3: Regular Air | N3: 42303 | O3: $0.24 | P3: $1.26 | Q3: $1.02 | R3: 8 | S3: $45.20 | T3: 0.03 | U3: $0.00 | V3: $45.90 | W3: $0.70 | X3: $46.91 | Y3: =VALUE(SUBSTITUTE(Table1[[#This Row],[Order Total]],"$","")) -> 45.9 | Z3: =VALUE(SUBSTITUTE(Table1[[#This Row],[Total]],"$","")) -> 46.91 | AA3: =Table1[[#This Row],[Order Total Number]]-Table1[[#This Row],[Total Number]] -> -1.01 | AB3: =VALUE(SUBSTITUTE(Table1[[#This Row],[Shipping Cost]],"$","")) -> 0.7 | AC3: =VALUE(SUBSTITUTE(Table1[[#This Row],[Discount $]],"$","")) -> 0 | AD3: =VALUE(SUBSTITUTE(Table1[[#This Row],[Retail Price]],"$","")) -> 1.26 | AE3: =(Table1[[#This Row],[Retail Price Number]]*Table1[[#This Row],[Order Quantity]])-Table1[[#This Row],[Discount $ Number]]+Table1[[#This Row],[Shipping Cost Number]] -> 10.78 | AF3: =Table1[[#This Row],[Retail Price Number]]*Table1[[#This Row],[Order Quantity]]-Table1[[#This Row],[Discount $ Number]] -> 10.08 | AG3: =(Table1[[#This Row],[Retail Price Number]]*Table1[[#This Row],[Order Quantity]])-Table1[[#This Row],[Discount $ Number]]-Table1[[#This Row],[Shipping Cost Number]] -> 9.38 | AH3: =Table1[[#This Row],[Retail Price Number]]*Table1[[#This Row],[Order Quantity]] -> 10.08 | AI3: =YEAR(Table1[[#This Row],[Order Date]]) -> 2015
A4: 5004-1 | B4: 41711 | C4: Dennis Pardue | D4: 412 Brunswick St,Fitzroy | E4: Melbourne | F4: VIC | G4: Consumer | H4: Connor Betts | I4: Not Specified | J4: TechSavi Cordless Navigator Duo | K4: Office Supplies | L4: Small Box | M4: Regular Air | N4: 41711 | O4: $42.11 | P4: $80.98 | Q4: $38.87 | R4: 45 | S4: $873.32 | T4: 0.04 | U4: $72.23 | V4: $837.57 | W4: $7.18 | X4: $82.58 | Y4: =VALUE(SUBSTITUTE(Table1[[#This Row],[Order Total]],"$","")) -> 837.57 | Z4: =VALUE(SUBSTITUTE(Table1[[#This Row],[Total]],"$","")) -> 82.58 | AA4: =Table1[[#This Row],[Order Total Number]]-Table1[[#This Row],[Total Number]] -> 754.99 | AB4: =VALUE(SUBSTITUTE(Table1[[#This Row],[Shipping Cost]],"$","")) -> 7.18 | AC4: =VALUE(SUBSTITUTE(Table1[[#This Row],[Discount $]],"$","")) -> 72.23 | AD4: =VALUE(SUBSTITUTE(Table1[[#This Row],[Retail Price]],"$","")) -> 80.98 | AE4: =(Table1[[#This Row],[Retail Price Number]]*Table1[[#This Row],[Order Quantity]])-Table1[[#This Row],[Discount $ Number]]+Table1[[#This Row],[Shipping Cost Number]] -> 3579.05 | AF4: =Table1[[#This Row],[Retail Price Number]]*Table1[[#This Row],[Order Quantity]]-Table1[[#This Row],[Discount $ Number]] -> 3571.87 | AG4: =(Table1[[#This Row],[Retail Price Number]]*Table1[[#This Row],[Order Quantity]])-Table1[[#This Row],[Discount $ Number]]-Table1[[#This Row],[Shipping Cost Number]] -> 3564.69 | AH4: =Table1[[#This Row],[Retail Price Number]]*Table1[[#This Row],[Order Quantity]] -> 3644.1 | AI4: =YEAR(Table1[[#This Row],[Order Date]]) -> 2014
A5: 5009-1 | B5: 41323 | C5: Sean Wendt | D5: 145 Ramsay St,Haberfield | E5: Sydney | F5: NSW | G5: Small Business | H5: Phoebe Gour | I5: Critical | J5: Artisan Printable Repositionable Plastic Tabs | K5: Office Supplies | L5: Wrap Bag | M5: Regular Air | N5: 41325 | O5: $5.33 | P5: $8.60 | Q5: $3.27 | R5: 16 | S5: $73.52 | T5: 0.01 | U5: $4.35 | V5: $740.67 | W5: $6.19 | X5: $730.92 | Y5: =VALUE(SUBSTITUTE(Table1[[#This Row],[Order Total]],"$","")) -> 740.67 | Z5: =VALUE(SUBSTITUTE(Table1[[#This Row],[Total]],"$","")) -> 730.92 | AA5: =Table1[[#This Row],[Order Total Number]]-Table1[[#This Row],[Total Number]] -> 9.75 | AB5: =VALUE(SUBSTITUTE(Table1[[#This Row],[Shipping Cost]],"$","")) -> 6.19 | AC5: =VALUE(SUBSTITUTE(Table1[[#This Row],[Discount $]],"$","")) -> 4.35 | AD5: =VALUE(SUBSTITUTE(Table1[[#This Row],[Retail Price]],"$","")) -> 8.6 | AE5: =(Table1[[#This Row],[Retail Price Number]]*Table1[[#This Row],[Order Quantity]])-Table1[[#This Row],[Discount $ Number]]+Table1[[#This Row],[Shipping Cost Number]] -> 139.44 | AF5: =Table1[[#This Row],[Retail Price Number]]*Table1[[#This Row],[Order Quantity]]-Table1[[#This Row],[Discount $ Number]] -> 133.25 | AG5: =(Table1[[#This Row],[Retail Price Number]]*Table1[[#This Row],[Order Quantity]])-Table1[[#This Row],[Discount $ Number]]-Table1[[#This Row],[Shipping Cost Number]] -> 127.06 | AH5: =Table1[[#This Row],[Retail Price Number]]*Table1[[#This Row],[Order Quantity]] -> 137.6 | AI5: =YEAR(Table1[[#This Row],[Order Date]]) -> 2013
A6: 5010-1 | B6: 41895 | C6: Christina Vanderzanden | D6: 188 Pitt Street,Sydney | E6: Sydney | F6: NSW | G6: Small Business | H6: Tina Carlton | I6: Not Specified | J6: Pizazz Drawing Pencil Set | K6: Office Supplies | L6: Wrap Bag | M6: Express Air | N6: 41899 | O6: $1.53 | P6: $2.78 | Q6: $1.25 | R6: 49 | S6: $138.46 | T6: 0.07 | U6: $5.95 | V6: $123.77 | W6: $1.34 | X6: $125.97 | Y6: =VALUE(SUBSTITUTE(Table1[[#This Row],[Order Total]],"$","")) -> 123.77 | Z6: =VALUE(SUBSTITUTE(Table1[[#This Row],[Total]],"$","")) -> 125.97 | AA6: =Table1[[#This Row],[Order Total Number]]-Table1[[#This Row],[Total Number]] -> -2.2 | AB6: =VALUE(SUBSTITUTE(Table1[[#This Row],[Shipping Cost]],"$","")) -> 1.34 | AC6: =VALUE(SUBSTITUTE(Table1[[#This Row],[Discount $]],"$","")) -> 5.95 | AD6: =VALUE(SUBSTITUTE(Table1[[#This Row],[Retail Price]],"$","")) -> 2.78 | AE6: =(Table1[[#This Row],[Retail Price Number]]*Table1[[#This Row],[Order Quantity]])-Table1[[#This Row],[Discount $ Number]]+Table1[[#This Row],[Shipping Cost Number]] -> 131.61 | AF6: =Table1[[#This Row],[Retail Price Number]]*Table1[[#This Row],[Order Quantity]]-Table1[[#This Row],[Discount $ Number]] -> 130.27 | AG6: =(Table1[[#This Row],[Retail Price Number]]*Table1[[#This Row],[Order Quantity]])-Table1[[#This Row],[Discount $ Number]]-Table1[[#This Row],[Shipping Cost Number]] -> 128.93 | AH6: =Table1[[#This Row],[Retail Price Number]]*Table1[[#This Row],[Order Quantity]] -> 136.22 | AI6: =YEAR(Table1[[#This Row],[Order Date]]) -> 2014
A7: 5011-1 | B7: 41602 | C7: Patrick OBrill | D7: 53 Riley Street,Woolloomooloo | E7: Sydney | F7: NSW | G7: Home Office | H7: Tina Carlton | I7: Not Specified | J7: Alto Parchment Paper, Assorted Colors | K7: Office Supplies | L7: Wrap Bag | M7: Regular Air | N7: 41604 | O7: $4.59 | P7: $7.28 | Q7: $2.69 | R7: 45 | S7: $197.36 | T7: 0.08 | U7: $12.98 | V7: $183.58 | W7: $11.15 | X7: $189.43 | Y7: =VALUE(SUBSTITUTE(Table1[[#This Row],[Order Total]],"$","")) -> 183.58 | Z7: =VALUE(SUBSTITUTE(Table1[[#This Row],[Total]],"$","")) -> 189.43 | AA7: =Table1[[#This Row],[Order Total Number]]-Table1[[#This Row],[Total Number]] -> -5.85 | AB7: =VALUE(SUBSTITUTE(Table1[[#This Row],[Shipping Cost]],"$","")) -> 11.15 | AC7: =VALUE(SUBSTITUTE(Table1[[#This Row],[Discount $]],"$","")) -> 12.98 | AD7: =VALUE(SUBSTITUTE(Table1[[#This Row],[Retail Price]],"$","")) -> 7.28 | AE7: =(Table1[[#This Row],[Retail Price Number]]*Table1[[#This Row],[Order Quantity]])-Table1[[#This Row],[Discount $ Number]]+Table1[[#This Row],[Shipping Cost Number]] -> 325.77 | AF7: =Table1[[#This Row],[Retail Price Number]]*Table1[[#This Row],[Order Quantity]]-Table1[[#This Row],[Discount $ Number]] -> 314.62 | AG7: =(Table1[[#This Row],[Retail Price Number]]*Table1[[#This Row],[Order Quantity]])-Table1[[#This Row],[Discount $ Number]]-Table1[[#This Row],[Shipping Cost Number]] -> 303.47 | AH7: =Table1[[#This Row],[Retail Price Number]]*Table1[[#This Row],[Order Quantity]] -> 327.6 | AI7: =YEAR(Table1[[#This Row],[Order Date]]) -> 2013
A8: 5012-1 | B8: 41889 | C8: Eugene Moren | D8: 85-113 Dunning Ave,Rosebery | E8: Sydney | F8: NSW | G8: Consumer | H8: Mihael Khan | I8: Not Specified | J8: Smiths Metal Binder Clips | K8: Office Supplies | L8: Small Box | M8: Regular Air | N8: 41889 | O8: $1.60 | P8: $2.62 | Q8: $1.02 | R8: 45 | S8: $65.50 | T8: 0.04 | U8: $5.90 | V8: $59.62 | W8: $0.80 | X8: $60.45 | Y8: =VALUE(SUBSTITUTE(Table1[[#This Row],[Order Total]],"$","")) -> 59.62 | Z8: =VALUE(SUBSTITUTE(Table1[[#This Row],[Total]],"$","")) -> 60.45 | AA8: =Table1[[#This Row],[Order Total Number]]-Table1[[#This Row],[Total Number]] -> -0.83 | AB8: =VALUE(SUBSTITUTE(Table1[[#This Row],[Shipping Cost]],"$","")) -> 0.8 | AC8: =VALUE(SUBSTITUTE(Table1[[#This Row],[Discount $]],"$","")) -> 5.9 | AD8: =VALUE(SUBSTITUTE(Table1[[#This Row],[Retail Price]],"$","")) -> 2.62 | AE8: =(Table1[[#This Row],[Retail Price Number]]*Table1[[#This Row],[Order Quantity]])-Table1[[#This Row],[Discount $ Number]]+Table1[[#This Row],[Shipping Cost Number]] -> 112.8 | AF8: =Table1[[#This Row],[Retail Price Number]]*Table1[[#This Row],[Order Quantity]]-Table1[[#This Row],[Discount $ Number]] -> 112 | AG8: =(Table1[[#This Row],[Retail Price Number]]*Table1[[#This Row],[Order Quantity]])-Table1[[#This Row],[Discount $ Number]]-Table1[[#This Row],[Shipping Cost Number]] -> 111.2 | AH8: =Table1[[#This Row],[Retail Price Number]]*Table1[[#This Row],[Order Quantity]] -> 117.9 | AI8: =YEAR(Table1[[#This Row],[Order Date]]) -> 2014
A9: 5012-1 | B9: 42032 | C9: Phillip Flathmann | D9: Macquarie Centre Cnr Herring Road & Waterloo Road,Macquarie Park | E9: Sydney | F9: NSW | G9: Home Office | H9: Nicholas Fernandes | I9: Medium | J9: Smiths Metal Binder Clips | K9: Technology | L9: Small Box | M9: Regular Air | N9: 42033 | O9: $1.60 | P9: $2.62 | Q9: $1.02 | R9: 34 | S9: $24.92 | T9: 0.02 | U9: $2.49 | V9: $22.43 | W9: $0.80 | X9: $27.43 | Y9: =VALUE(SUBSTITUTE(Table1[[#This Row],[Order Total]],"$","")) -> 22.43 | Z9: =VALUE(SUBSTITUTE(Table1[[#This Row],[Total]],"$","")) -> 27.43 | AA9: =Table1[[#This Row],[Order Total Number]]-Table1[[#This Row],[Total Number]] -> -5 | AB9: =VALUE(SUBSTITUTE(Table1[[#This Row],[Shipping Cost]],"$","")) -> 0.8 | AC9: =VALUE(SUBSTITUTE(Table1[[#This Row],[Discount $]],"$","")) -> 2.49 | AD9: =VALUE(SUBSTITUTE(Table1[[#This Row],[Retail Price]],"$","")) -> 2.62 | AE9: =(Table1[[#This Row],[Retail Price Number]]*Table1[[#This Row],[Order Quantity]])-Table1[[#This Row],[Discount $ Number]]+Table1[[#This Row],[Shipping Cost Number]] -> 87.39 | AF9: =Table1[[#This Row],[Retail Price Number]]*Table1[[#This Row],[Order Quantity]]-Table1[[#This Row],[Discount $ Number]] -> 86.59 | AG9: =(Table1[[#This Row],[Retail Price Number]]*Table1[[#This Row],[Order Quantity]])-Table1[[#This Row],[Discount $ Number]]-Table1[[#This Row],[Shipping Cost Number]] -> 85.79 | AH9: =Table1[[#This Row],[Retail Price Number]]*Table1[[#This Row],[Order Quantity]] -> 89.08 | AI9: =YEAR(Table1[[#This Row],[Order Date]]) -> 2015
A10: 5014-1 | B10: 41798 | C10: John Lee | D10: 180 High Street,Windsor | E10: Melbourne | F10: VIC | G10: Home Office | H10: Connor Betts | I10: Not Specified | J10: Artisan Hole Reinforcements | K10: Office Supplies | L10: Wrap Bag | M10: Regular Air | N10: 41800 | O10: $3.99 | P10: $6.23 | Q10: $2.24 | R10: 25 | S10: $194.36 | T10: 0.1 | U10: $15.93 | V10: $178.12 | W10: $6.97 | X10: $189.45 | Y10: =VALUE(SUBSTITUTE(Table1[[#This Row],[Order Total]],"$","")) -> 178.12 | Z10: =VALUE(SUBSTITUTE(Table1[[#This Row],[Total]],"$","")) -> 189.45 | AA10: =Table1[[#This Row],[Order Total Number]]-Table1[[#This Row],[Total Number]] -> -11.33 | AB10: =VALUE(SUBSTITUTE(Table1[[#This Row],[Shipping Cost]],"$","")) -> 6.97 | AC10: =VALUE(SUBSTITUTE(Table1[[#This Row],[Discount $]],"$","")) -> 15.93 | AD10: =VALUE(SUBSTITUTE(Table1[[#This Row],[Retail Price]],"$","")) -> 6.23 | AE10: =(Table1[[#This Row],[Retail Price Number]]*Table1[[#This Row],[Order Quantity]])-Table1[[#This Row],[Discount $ Number]]+Table1[[#This Row],[Shipping Cost Number]] -> 146.79 | AF10: =Table1[[#This Row],[Retail Price Number]]*Table1[[#This Row],[Order Quantity]]-Table1[[#This Row],[Discount $ Number]] -> 139.82 | AG10: =(Table1[[#This Row],[Retail Price Number]]*Table1[[#This Row],[Order Quantity]])-Table1[[#This Row],[Discount $ Number]]-Table1[[#This Row],[Shipping Cost Number]] -> 132.85 | AH10: =Table1[[#This Row],[Retail Price Number]]*Table1[[#This Row],[Order Quantity]] -> 155.75 | AI10: =YEAR(Table1[[#This Row],[Order Date]]) -> 2014
A11: 5015-1 | B11: 41914 | C11: Ritsa Hightower | D11: 1/160 Anzac Parade,Kensington | E11: Sydney | F11: NSW | G11: Corporate | H11: Natasha Song | I11: Critical | J11: UGen Ultra Professional Cordless Optical Suite | K11: Office Supplies | L11: Small Box | M11: Regular Air | N11: 41916 | O11: $156.50 | P11: $300.97 | Q11: $144.47 | R11: 42 | S11: $1,079.62 | T11: 0.04 | U11: $30.83 | V11: $1,753.33 | W11: $7.18 | X11: $1,705.42 | Y11: =VALUE(SUBSTITUTE(Table1[[#This Row],[Order Total]],"$","")) -> 1753.33 | Z11: =VALUE(SUBSTITUTE(Table1[[#This Row],[Total]],"$","")) -> 1705.42 | AA11: =Table1[[#This Row],[Order Total Number]]-Table1[[#This Row],[Total Number]] -> 47.91 | AB11: =VALUE(SUBSTITUTE(Table1[[#This Row],[Shipping Cost]],"$","")) -> 7.18 | AC11: =VALUE(SUBSTITUTE(Table1[[#This Row],[Discount $]],"$","")) -> 30.83 | AD11: =VALUE(SUBSTITUTE(Table1[[#This Row],[Retail Price]],"$","")) -> 300.97 | AE11: =(Table1[[#This Row],[Retail Price Number]]*Table1[[#This Row],[Order Quantity]])-Table1[[#This Row],[Discount $ Number]]+Table1[[#This Row],[Shipping Cost Number]] -> 12617.09 | AF11: =Table1[[#This Row],[Retail Price Number]]*Table1[[#This Row],[Order Quantity]]-Table1[[#This Row],[Discount $ Number]] -> 12609.91 | AG11: =(Table1[[#This Row],[Retail Price Number]]*Table1[[#This Row],[Order Quantity]])-Table1[[#This Row],[Discount $ Number]]-Table1[[#This Row],[Shipping Cost Number]] -> 12602.73 | AH11: =Table1[[#This Row],[Retail Price Number]]*Table1[[#This Row],[Order Quantity]] -> 12640.74 | AI11: =YEAR(Table1[[#This Row],[Order Date]]) -> 2014
A12: 5015-1 | B12: 41730 | C12: Anne Pryor | D12: 1-2/299 Sussex St,Sydney | E12: Sydney | F12: NSW | G12: Corporate | H12: Aanya Zhang | I12: Medium | J12: UGen Ultra Professional Cordless Optical Suite | K12: Office Supplies | L12: Wrap Bag | M12: Express Air | N12: 41731 | O12: $156.50 | P12: $300.97 | Q12: $144.47 | R12: 3 | S12: $1,602.02 | T12: 0.1 | U12: $144.41 | V12: $1,513.83 | W12: $7.18 | X12: $1,533.62 | Y12: =VALUE(SUBSTITUTE(Table1[[#This Row],[Order Total]],"$","")) -> 1513.83 | Z12: =VALUE(SUBSTITUTE(Table1[[#This Row],[Total]],"$","")) -> 1533.62 | AA12: =Table1[[#This Row],[Order Total Number]]-Table1[[#This Row],[Total Number]] -> -19.79 | AB12: =VALUE(SUBSTITUTE(Table1[[#This Row],[Shipping Cost]],"$","")) -> 7.18 | AC12: =VALUE(SUBSTITUTE(Table1[[#This Row],[Discount $]],"$","")) -> 144.41 | AD12: =VALUE(SUBSTITUTE(Table1[[#This Row],[Retail Price]],"$","")) -> 300.97 | AE12: =(Table1[[#This Row],[Retail Price Number]]*Table1[[#This Row],[Order Quantity]])-Table1[[#This Row],[Discount $ Number]]+Table1[[#This Row],[Shipping Cost Number]] -> 765.68 | AF12: =Table1[[#This Row],[Retail Price Number]]*Table1[[#This Row],[Order Quantity]]-Table1[[#This Row],[Discount $ Number]] -> 758.5 | AG12: =(Table1[[#This Row],[Retail Price Number]]*Table1[[#This Row],[Order Quantity]])-Table1[[#This Row],[Discount $ Number]]-Table1[[#This Row],[Shipping Cost Number]] -> 751.32 | AH12: =Table1[[#This Row],[Retail Price Number]]*Table1[[#This Row],[Order Quantity]] -> 902.91 | AI12: =YEAR(Table1[[#This Row],[Order Date]]) -> 2014
A13: 5016-1 | B13: 41316 | C13: Alex Russell | D13: 99 Lygon Street,East Brunswick | E13: Melbourne | F13: VIC | G13: Consumer | H13: Connor Betts | I13: Low | J13: DrawIt Pizazz Watercolor Pencils, 10-Color Set with Brush | K13: Office Supplies | L13: Wrap Bag | M13: Regular Air | N13: 41317 | O13: $2.39 | P13: $4.26 | Q13: $1.87 | R13: 18 | S13: $123.54 | T13: 0.06 | U13: $3.71 | V13: $119.83 | W13: $1.20 | X13: $121.03 | Y13: =VALUE(SUBSTITUTE(Table1[[#This Row],[Order Total]],"$","")) -> 119.83 | Z13: =VALUE(SUBSTITUTE(Table1[[#This Row],[Total]],"$","")) -> 121.03 | AA13: =Table1[[#This Row],[Order Total Number]]-Table1[[#This Row],[Total Number]] -> -1.2 | AB13: =VALUE(SUBSTITUTE(Table1[[#This Row],[Shipping Cost]],"$","")) -> 1.2 | AC13: =VALUE(SUBSTITUTE(Table1[[#This Row],[Discount $]],"$","")) -> 3.71 | AD13: =VALUE(SUBSTITUTE(Table1[[#This Row],[Retail Price]],"$","")) -> 4.26 | AE13: =(Table1[[#This Row],[Retail Price Number]]*Table1[[#This Row],[Order Quantity]])-Table1[[#This Row],[Discount $ Number]]+Table1[[#This Row],[Shipping Cost Number]] -> 74.17 | AF13: =Table1[[#This Row],[Retail Price Number]]*Table1[[#This Row],[Order Quantity]]-Table1[[#This Row],[Discount $ Number]] -> 72.97 | AG13: =(Table1[[#This Row],[Retail Price Number]]*Table1[[#This Row],[Order Quantity]])-Table1[[#This Row],[Discount $ Number]]-Table1[[#This Row],[Shipping Cost Number]] -> 71.77 | AH13: =Table1[[#This Row],[Retail Price Number]]*Table1[[#This Row],[Order Quantity]] -> 76.68 | AI13: =YEAR(Table1[[#This Row],[Order Date]]) -> 2013
... A1412: 5428-1 | B1412: 41695 | C1412: Rick Hansen | D1412: Macquarie Centre Cnr Herring Road & Waterloo Road,Macquarie Park | E1412: Sydney | F1412: NSW | G1412: Consumer | H1412: Nicholas Fernandes | I1412: High | J1412: Creator Colored Pencils | K1412: Office Supplies | L1412: Wrap Bag | M1412: Regular Air | N1412: 41696 | O1412: $1.57 | P1412: $3.28 | Q1412: $1.71 | R1412: 29 | S1412: $85.28 | T1412: 0.03 | U1412: $6.82 | V1412: $78.46 | W1412: $0.98 | X1412: $79.44 | Y1412: =VALUE(SUBSTITUTE(Table1[[#This Row],[Order Total]],"$","")) -> 78.46 | Z1412: =VALUE(SUBSTITUTE(Table1[[#This Row],[Total]],"$","")) -> 79.44 | AA1412: =Table1[[#This Row],[Order Total Number]]-Table1[[#This Row],[Total Number]] -> -0.98 | AB1412: =VALUE(SUBSTITUTE(Table1[[#This Row],[Shipping Cost]],"$","")) -> 0.98 | AC1412: =VALUE(SUBSTITUTE(Table1[[#This Row],[Discount $]],"$","")) -> 6.82 | AD1412: =VALUE(SUBSTITUTE(Table1[[#This Row],[Retail Price]],"$","")) -> 3.28 | AE1412: =(Table1[[#This Row],[Retail Price Number]]*Table1[[#This Row],[Order Quantity]])-Table1[[#This Row],[Discount $ Number]]+Table1[[#This Row],[Shipping Cost Number]] -> 89.28 | AF1412: =Table1[[#This Row],[Retail Price Number]]*Table1[[#This Row],[Order Quantity]]-Table1[[#This Row],[Discount $ Number]] -> 88.3 | AG1412: =(Table1[[#This Row],[Retail Price Number]]*Table1[[#This Row],[Order Quantity]])-Table1[[#This Row],[Discount $ Number]]-Table1[[#This Row],[Shipping Cost Number]] -> 87.32 | AH1412: =Table1[[#This Row],[Retail Price Number]]*Table1[[#This Row],[Order Quantity]] -> 95.12 | AI1412: =YEAR(Table1[[#This Row],[Order Date]]) -> 2014
A1413: 5428-1 | B1413: 41695 | C1413: Jhrip Luxen | D1413: 4A Lyons St,Strathfield | E1413: Sydney | F1413: NSW | G1413: Home Office | H1413: Tina Carlton | I1413: High | J1413: Creator Colored Pencils | K1413: Furniture | L1413: Large Box | M1413: Regular Air | N1413: 41696 | O1413: $1.57 | P1413: $3.28 | Q1413: $1.71 | S1413: $85.28 | T1413: 0.04 | U1413: $6.82 | V1413: $78.46 | W1413: $0.98 | X1413: $79.44 | Y1413: =VALUE(SUBSTITUTE(Table1[[#This Row],[Order Total]],"$","")) -> 78.46 | Z1413: =VALUE(SUBSTITUTE(Table1[[#This Row],[Total]],"$","")) -> 79.44 | AA1413: =Table1[[#This Row],[Order Total Number]]-Table1[[#This Row],[Total Number]] -> -0.98 | AB1413: =VALUE(SUBSTITUTE(Table1[[#This Row],[Shipping Cost]],"$","")) -> 0.98 | AC1413: =VALUE(SUBSTITUTE(Table1[[#This Row],[Discount $]],"$","")) -> 6.82 | AD1413: =VALUE(SUBSTITUTE(Table1[[#This Row],[Retail Price]],"$","")) -> 3.28 | AE1413: =(Table1[[#This Row],[Retail Price Number]]*Table1[[#This Row],[Order Quantity]])-Table1[[#This Row],[Discount $ Number]]+Table1[[#This Row],[Shipping Cost Number]] -> -5.84 | AF1413: =Table1[[#This Row],[Retail Price Number]]*Table1[[#This Row],[Order Quantity]]-Table1[[#This Row],[Discount $ Number]] -> -6.82 | AG1413: =(Table1[[#This Row],[Retail Price Number]]*Table1[[#This Row],[Order Quantity]])-Table1[[#This Row],[Discount $ Number]]-Table1[[#This Row],[Shipping Cost Number]] -> -7.8 | AH1413: =Table1[[#This Row],[Retail Price Number]]*Table1[[#This Row],[Order Quantity]] -> 0 | AI1413: =YEAR(Table1[[#This Row],[Order Date]]) -> 2014
A1414: 5429-1 | B1414: 41363 | C1414: Justin Knight | D1414: Macquarie Centre Cnr Herring Road & Waterloo Road,Macquarie Park | E1414: Sydney | F1414: NSW | G1414: Small Business | H1414: Nicholas Fernandes | I1414: Not Specified | J1414: Artisan Binder Labels | K1414: Office Supplies | L1414: Small Box | M1414: Regular Air | N1414: 41364 | O1414: $2.45 | P1414: $3.89 | Q1414: $1.44 | R1414: 8 | S1414: $52.93 | T1414: 0.07 | U1414: $0.17 | V1414: $59.33 | W1414: $7.01 | X1414: $60.68 | Y1414: =VALUE(SUBSTITUTE(Table1[[#This Row],[Order Total]],"$","")) -> 59.33 | Z1414: =VALUE(SUBSTITUTE(Table1[[#This Row],[Total]],"$","")) -> 60.68 | AA1414: =Table1[[#This Row],[Order Total Number]]-Table1[[#This Row],[Total Number]] -> -1.35 | AB1414: =VALUE(SUBSTITUTE(Table1[[#This Row],[Shipping Cost]],"$","")) -> 7.01 | AC1414: =VALUE(SUBSTITUTE(Table1[[#This Row],[Discount $]],"$","")) -> 0.17 | AD1414: =VALUE(SUBSTITUTE(Table1[[#This Row],[Retail Price]],"$","")) -> 3.89 | AE1414: =(Table1[[#This Row],[Retail Price Number]]*Table1[[#This Row],[Order Quantity]])-Table1[[#This Row],[Discount $ Number]]+Table1[[#This Row],[Shipping Cost Number]] -> 37.96 | AF1414: =Table1[[#This Row],[Retail Price Number]]*Table1[[#This Row],[Order Quantity]]-Table1[[#This Row],[Discount $ Number]] -> 30.95 | AG1414: =(Table1[[#This Row],[Retail Price Number]]*Table1[[#This Row],[Order Quantity]])-Table1[[#This Row],[Discount $ Number]]-Table1[[#This Row],[Shipping Cost Number]] -> 23.94 | AH1414: =Table1[[#This Row],[Retail Price Number]]*Table1[[#This Row],[Order Quantity]] -> 31.12 | AI1414: =YEAR(Table1[[#This Row],[Order Date]]) -> 2013
A1415: 5429-1 | B1415: 41798 | C1415: John Lee | D1415: 180 High Street,Windsor | E1415: Melbourne | F1415: VIC | G1415: Small Business | H1415: Connor Betts | I1415: High | J1415: Bagged Rubber Bands | K1415: Office Supplies | L1415: Small Box | M1415: Express Air | N1415: 41800 | O1415: $0.24 | P1415: $1.26 | Q1415: $1.02 | R1415: 27 | S1415: $90.08 | T1415: 0 | U1415: $5.44 | V1415: $80.62 | W1415: $0.70 | X1415: $83.57 | Y1415: =VALUE(SUBSTITUTE(Table1[[#This Row],[Order Total]],"$","")) -> 80.62 | Z1415: =VALUE(SUBSTITUTE(Table1[[#This Row],[Total]],"$","")) -> 83.57 | AA1415: =Table1[[#This Row],[Order Total Number]]-Table1[[#This Row],[Total Number]] -> -2.95 | AB1415: =VALUE(SUBSTITUTE(Table1[[#This Row],[Shipping Cost]],"$","")) -> 0.7 | AC1415: =VALUE(SUBSTITUTE(Table1[[#This Row],[Discount $]],"$","")) -> 5.44 | AD1415: =VALUE(SUBSTITUTE(Table1[[#This Row],[Retail Price]],"$","")) -> 1.26 | AE1415: =(Table1[[#This Row],[Retail Price Number]]*Table1[[#This Row],[Order Quantity]])-Table1[[#This Row],[Discount $ Number]]+Table1[[#This Row],[Shipping Cost Number]] -> 29.28 | AF1415: =Table1[[#This Row],[Retail Price Number]]*Table1[[#This Row],[Order Quantity]]-Table1[[#This Row],[Discount $ Number]] -> 28.58 | AG1415: =(Table1[[#This Row],[Retail Price Number]]*Table1[[#This Row],[Order Quantity]])-Table1[[#This Row],[Discount $ Number]]-Table1[[#This Row],[Shipping Cost Number]] -> 27.88 | AH1415: =Table1[[#This Row],[Retail Price Number]]*Table1[[#This Row],[Order Quantity]] -> 34.02 | AI1415: =YEAR(Table1[[#This Row],[Order Date]]) -> 2014
A1416: 5429-1 | B1416: 41579 | C1416: Kristina Nunn | D1416: 22 Civic Rd,Auburn | E1416: Sydney | F1416: NSW | G1416: Small Business | H1416: Mihael Khan | I1416: Low | J1416: Artisan 48 Labels | K1416: Technology | L1416: Jumbo Drum | M1416: Delivery Truck | N1416: 41580 | O1416: $3.84 | P1416: $6.30 | Q1416: $2.46 | R1416: 47 | S1416: $136.04 | T1416: 0.02 | U1416: $5.05 | V1416: $121.83 | W1416: $0.50 | X1416: $132.95 | Y1416: =VALUE(SUBSTITUTE(Table1[[#This Row],[Order Total]],"$","")) -> 121.83 | Z1416: =VALUE(SUBSTITUTE(Table1[[#This Row],[Total]],"$","")) -> 132.95 | AA1416: =Table1[[#This Row],[Order Total Number]]-Table1[[#This Row],[Total Number]] -> -11.12 | AB1416: =VALUE(SUBSTITUTE(Table1[[#This Row],[Shipping Cost]],"$","")) -> 0.5 | AC1416: =VALUE(SUBSTITUTE(Table1[[#This Row],[Discount $]],"$","")) -> 5.05 | AD1416: =VALUE(SUBSTITUTE(Table1[[#This Row],[Retail Price]],"$","")) -> 6.3 | AE1416: =(Table1[[#This Row],[Retail Price Number]]*Table1[[#This Row],[Order Quantity]])-Table1[[#This Row],[Discount $ Number]]+Table1[[#This Row],[Shipping Cost Number]] -> 291.55 | AF1416: =Table1[[#This Row],[Retail Price Number]]*Table1[[#This Row],[Order Quantity]]-Table1[[#This Row],[Discount $ Number]] -> 291.05 | AG1416: =(Table1[[#This Row],[Retail Price Number]]*Table1[[#This Row],[Order Quantity]])-Table1[[#This Row],[Discount $ Number]]-Table1[[#This Row],[Shipping Cost Number]] -> 290.55 | AH1416: =Table1[[#This Row],[Retail Price Number]]*Table1[[#This Row],[Order Quantity]] -> 296.1 | AI1416: =YEAR(Table1[[#This Row],[Order Date]]) -> 2013
A1417: 5429-1 | B1417: 41425 | C1417: Raymond Fair | D1417: 188 Pitt Street,Sydney | E1417: Sydney | F1417: NSW | G1417: Small Business | H1417: Tina Carlton | I1417: Critical | J1417: Apex Box Cutter Scissors | K1417: Office Supplies | L1417: Small Box | M1417: Express Air | N1417: 41427 | O1417: $4.19 | P1417: $10.23 | Q1417: $6.04 | R1417: 42 | S1417: $465.56 | T1417: 0.07 | U1417: $18.56 | V1417: $422.10 | W1417: $4.68 | X1417: $423.29 | Y1417: =VALUE(SUBSTITUTE(Table1[[#This Row],[Order Total]],"$","")) -> 422.1 | Z1417: =VALUE(SUBSTITUTE(Table1[[#This Row],[Total]],"$","")) -> 423.29 | AA1417: =Table1[[#This Row],[Order Total Number]]-Table1[[#This Row],[Total Number]] -> -1.19 | AB1417: =VALUE(SUBSTITUTE(Table1[[#This Row],[Shipping Cost]],"$","")) -> 4.68 | AC1417: =VALUE(SUBSTITUTE(Table1[[#This Row],[Discount $]],"$","")) -> 18.56 | AD1417: =VALUE(SUBSTITUTE(Table1[[#This Row],[Retail Price]],"$","")) -> 10.23 | AE1417: =(Table1[[#This Row],[Retail Price Number]]*Table1[[#This Row],[Order Quantity]])-Table1[[#This Row],[Discount $ Number]]+Table1[[#This Row],[Shipping Cost Number]] -> 415.78 | AF1417: =Table1[[#This Row],[Retail Price Number]]*Table1[[#This Row],[Order Quantity]]-Table1[[#This Row],[Discount $ Number]] -> 411.1 | AG1417: =(Table1[[#This Row],[Retail Price Number]]*Table1[[#This Row],[Order Quantity]])-Table1[[#This Row],[Discount $ Number]]-Table1[[#This Row],[Shipping Cost Number]] -> 406.42 | AH1417: =Table1[[#This Row],[Retail Price Number]]*Table1[[#This Row],[Order Quantity]] -> 429.66 | AI1417: =YEAR(Table1[[#This Row],[Order Date]]) -> 2013
A1418: 5429-1 | B1418: 41774 | C1418: Eric Barreto | D1418: 359 Crown Street,Surry Hills | E1418: Sydney | F1418: NSW | G1418: Corporate | H1418: Phoebe Gour | I1418: High | J1418: Lumi Crayons | K1418: Furniture | L1418: Small Pack | M1418: Regular Air | N1418: 41775 | O1418: $5.22 | P1418: $9.85 | Q1418: $4.63 | R1418: 1 | S1418: $89.50 | T1418: 0.1 | U1418: $0.00 | V1418: $89.50 | W1418: $4.82 | X1418: $94.97 | Y1418: =VALUE(SUBSTITUTE(Table1[[#This Row],[Order Total]],"$","")) -> 89.5 | Z1418: =VALUE(SUBSTITUTE(Table1[[#This Row],[Total]],"$","")) -> 94.97 | AA1418: =Table1[[#This Row],[Order Total Number]]-Table1[[#This Row],[Total Number]] -> -5.47 | AB1418: =VALUE(SUBSTITUTE(Table1[[#This Row],[Shipping Cost]],"$","")) -> 4.82 | AC1418: =VALUE(SUBSTITUTE(Table1[[#This Row],[Discount $]],"$","")) -> 0 | AD1418: =VALUE(SUBSTITUTE(Table1[[#This Row],[Retail Price]],"$","")) -> 9.85 | AE1418: =(Table1[[#This Row],[Retail Price Number]]*Table1[[#This Row],[Order Quantity]])-Table1[[#This Row],[Discount $ Number]]+Table1[[#This Row],[Shipping Cost Number]] -> 14.67 | AF1418: =Table1[[#This Row],[Retail Price Number]]*Table1[[#This Row],[Order Quantity]]-Table1[[#This Row],[Discount $ Number]] -> 9.85 | AG1418: =(Table1[[#This Row],[Retail Price Number]]*Table1[[#This Row],[Order Quantity]])-Table1[[#This Row],[Discount $ Number]]-Table1[[#This Row],[Shipping Cost Number]] -> 5.03 | AH1418: =Table1[[#This Row],[Retail Price Number]]*Table1[[#This Row],[Order Quantity]] -> 9.85 | AI1418: =YEAR(Table1[[#This Row],[Order Date]]) -> 2014
A1419: 5429-1 | B1419: 41425 | C1419: Raymond Fair | D1419: 188 Pitt Street,Sydney | E1419: Sydney | F1419: NSW | G1419: Home Office | H1419: Tina Carlton | I1419: Not Specified | J1419: EcoTones Memo Sheets | K1419: Office Supplies | L1419: Wrap Bag | M1419: Regular Air | N1419: 41427 | O1419: $2.52 | P1419: $4.00 | Q1419: $1.48 | R1419: 41 | S1419: $125.00 | T1419: 0.07 | U1419: $12.54 | V1419: $121.74 | W1419: $1.30 | X1419: $122.74 | Y1419: =VALUE(SUBSTITUTE(Table1[[#This Row],[Order Total]],"$","")) -> 121.74 | Z1419: =VALUE(SUBSTITUTE(Table1[[#This Row],[Total]],"$","")) -> 122.74 | AA1419: =Table1[[#This Row],[Order Total Number]]-Table1[[#This Row],[Total Number]] -> -1 | AB1419: =VALUE(SUBSTITUTE(Table1[[#This Row],[Shipping Cost]],"$","")) -> 1.3 | AC1419: =VALUE(SUBSTITUTE(Table1[[#This Row],[Discount $]],"$","")) -> 12.54 | AD1419: =VALUE(SUBSTITUTE(Table1[[#This Row],[Retail Price]],"$","")) -> 4 | AE1419: =(Table1[[#This Row],[Retail Price Number]]*Table1[[#This Row],[Order Quantity]])-Table1[[#This Row],[Discount $ Number]]+Table1[[#This Row],[Shipping Cost Number]] -> 152.76 | AF1419: =Table1[[#This Row],[Retail Price Number]]*Table1[[#This Row],[Order Quantity]]-Table1[[#This Row],[Discount $ Number]] -> 151.46 | AG1419: =(Table1[[#This Row],[Retail Price Number]]*Table1[[#This Row],[Order Quantity]])-Table1[[#This Row],[Discount $ Number]]-Table1[[#This Row],[Shipping Cost Number]] -> 150.16 | AH1419: =Table1[[#This Row],[Retail Price Number]]*Table1[[#This Row],[Order Quantity]] -> 164 | AI1419: =YEAR(Table1[[#This Row],[Order Date]]) -> 2013
A1420: 5429-1 | B1420: 42024 | C1420: Saphhira Shifley | D1420: Westfield Miranda, 600 Kingsway,Miranda | E1420: Sydney | F1420: NSW | G1420: Corporate | H1420: Preston Senome | I1420: Critical | J1420: Artisan 479 Labels | K1420: Office Supplies | L1420: Small Box | M1420: Regular Air | N1420: 42025 | O1420: $1.59 | P1420: $2.61 | Q1420: $1.02 | R1420: 8 | S1420: $127.24 | T1420: 0.04 | U1420: $11.12 | V1420: $127.76 | W1420: $0.50 | X1420: $122.16 | Y1420: =VALUE(SUBSTITUTE(Table1[[#This Row],[Order Total]],"$","")) -> 127.76 | Z1420: =VALUE(SUBSTITUTE(Table1[[#This Row],[Total]],"$","")) -> 122.16 | AA1420: =Table1[[#This Row],[Order Total Number]]-Table1[[#This Row],[Total Number]] -> 5.6 | AB1420: =VALUE(SUBSTITUTE(Table1[[#This Row],[Shipping Cost]],"$","")) -> 0.5 | AC1420: =VALUE(SUBSTITUTE(Table1[[#This Row],[Discount $]],"$","")) -> 11.12 | AD1420: =VALUE(SUBSTITUTE(Table1[[#This Row],[Retail Price]],"$","")) -> 2.61 | AE1420: =(Table1[[#This Row],[Retail Price Number]]*Table1[[#This Row],[Order Quantity]])-Table1[[#This Row],[Discount $ Number]]+Table1[[#This Row],[Shipping Cost Number]] -> 10.26 | AF1420: =Table1[[#This Row],[Retail Price Number]]*Table1[[#This Row],[Order Quantity]]-Table1[[#This Row],[Discount $ Number]] -> 9.76 | AG1420: =(Table1[[#This Row],[Retail Price Number]]*Table1[[#This Row],[Order Quantity]])-Table1[[#This Row],[Discount $ Number]]-Table1[[#This Row],[Shipping Cost Number]] -> 9.26 | AH1420: =Table1[[#This Row],[Retail Price Number]]*Table1[[#This Row],[Order Quantity]] -> 20.88 | AI1420: =YEAR(Table1[[#This Row],[Order Date]]) -> 2015
A1421: 5429-1 | B1421: 41572 | C1421: Dan Campbell | D1421: 1/173-179 Bronte Rd,Waverley | E1421: Sydney | F1421: NSW | G1421: Corporate | H1421: Leighton Forrest | I1421: Medium | J1421: Artisan 481 Labels | K1421: Office Supplies | L1421: Wrap Bag | M1421: Regular Air | N1421: 41574 | O1421: $1.94 | P1421: $3.08 | Q1421: $1.14 | R1421: 20 | S1421: $452.00 | T1421: 0.06 | U1421: $45.28 | V1421: $412.00 | W1421: $0.99 | X1421: $413.99 | Y1421: =VALUE(SUBSTITUTE(Table1[[#This Row],[Order Total]],"$","")) -> 412 | Z1421: =VALUE(SUBSTITUTE(Table1[[#This Row],[Total]],"$","")) -> 413.99 | AA1421: =Table1[[#This Row],[Order Total Number]]-Table1[[#This Row],[Total Number]] -> -1.99 | AB1421: =VALUE(SUBSTITUTE(Table1[[#This Row],[Shipping Cost]],"$","")) -> 0.99 | AC1421: =VALUE(SUBSTITUTE(Table1[[#This Row],[Discount $]],"$","")) -> 45.28 | AD1421: =VALUE(SUBSTITUTE(Table1[[#This Row],[Retail Price]],"$","")) -> 3.08 | AE1421: =(Table1[[#This Row],[Retail Price Number]]*Table1[[#This Row],[Order Quantity]])-Table1[[#This Row],[Discount $ Number]]+Table1[[#This Row],[Shipping Cost Number]] -> 17.31 | AF1421: =Table1[[#This Row],[Retail Price Number]]*Table1[[#This Row],[Order Quantity]]-Table1[[#This Row],[Discount $ Number]] -> 16.32 | AG1421: =(Table1[[#This Row],[Retail Price Number]]*Table1[[#This Row],[Order Quantity]])-Table1[[#This Row],[Discount $ Number]]-Table1[[#This Row],[Shipping Cost Number]] -> 15.33 | AH1421: =Table1[[#This Row],[Retail Price Number]]*Table1[[#This Row],[Order Quantity]] -> 61.6 | AI1421: =YEAR(Table1[[#This Row],[Order Date]]) -> 2013
A1422: 5430-1 | B1422: 41695 | C1422: Gary Hwang | D1422: 60 York St,Sydney | E1422: Sydney | F1422: NSW | G1422: Corporate | H1422: Charlie Bui | I1422: Medium | J1422: Steady Major Accent Highlighters | K1422: Office Supplies | L1422: Small Box | M1422: Regular Air | N1422: 41697 | O1422: $3.75 | P1422: $7.08 | Q1422: $3.33 | R1422: 27 | S1422: $220.44 | T1422: 0.04 | U1422: $6.61 | V1422: $213.83 | W1422: $2.35 | X1422: $215.33 | Y1422: =VALUE(SUBSTITUTE(Table1[[#This Row],[Order Total]],"$","")) -> 213.83 | Z1422: =VALUE(SUBSTITUTE(Table1[[#This Row],[Total]],"$","")) -> 215.33 | AA1422: =Table1[[#This Row],[Order Total Number]]-Table1[[#This Row],[Total Number]] -> -1.5 | AB1422: =VALUE(SUBSTITUTE(Table1[[#This Row],[Shipping Cost]],"$","")) -> 2.35 | AC1422: =VALUE(SUBSTITUTE(Table1[[#This Row],[Discount $]],"$","")) -> 6.61 | AD1422: =VALUE(SUBSTITUTE(Table1[[#This Row],[Retail Price]],"$","")) -> 7.08 | AE1422: =(Table1[[#This Row],[Retail Price Number]]*Table1[[#This Row],[Order Quantity]])-Table1[[#This Row],[Discount $ Number]]+Table1[[#This Row],[Shipping Cost Number]] -> 186.9 | AF1422: =Table1[[#This Row],[Retail Price Number]]*Table1[[#This Row],[Order Quantity]]-Table1[[#This Row],[Discount $ Number]] -> 184.55 | AG1422: =(Table1[[#This Row],[Retail Price Number]]*Table1[[#This Row],[Order Quantity]])-Table1[[#This Row],[Discount $ Number]]-Table1[[#This Row],[Shipping Cost Number]] -> 182.2 | AH1422: =Table1[[#This Row],[Retail Price Number]]*Table1[[#This Row],[Order Quantity]] -> 191.16 | AI1422: =YEAR(Table1[[#This Row],[Order Date]]) -> 2014
A1423: 5430-1 | B1423: 42342 | C1423: Cari Schnelling | D1423: 273 George Street,Sydney | E1423: Sydney | F1423: NSW | G1423: Home Office | H1423: Leighton Forrest | I1423: Critical | J1423: Assorted Color Push Pins | K1423: Office Supplies | L1423: Wrap Bag | M1423: Regular Air | N1423: 42341 | O1423: $0.87 | P1423: $1.81 | Q1423: $0.94 | R1423: 36 | S1423: $80.64 | T1423: 0.01 | U1423: $8.06 | V1423: $72.58 | W1423: $0.75 | X1423: $73.58 | Y1423: =VALUE(SUBSTITUTE(Table1[[#This Row],[Order Total]],"$","")) -> 72.58 | Z1423: =VALUE(SUBSTITUTE(Table1[[#This Row],[Total]],"$","")) -> 73.58 | AA1423: =Table1[[#This Row],[Order Total Number]]-Table1[[#This Row],[Total Number]] -> -1 | AB1423: =VALUE(SUBSTITUTE(Table1[[#This Row],[Shipping Cost]],"$","")) -> 0.75 | AC1423: =VALUE(SUBSTITUTE(Table1[[#This Row],[Discount $]],"$","")) -> 8.06 | AD1423: =VALUE(SUBSTITUTE(Table1[[#This Row],[Retail Price]],"$","")) -> 1.81 | AE1423: =(Table1[[#This Row],[Retail Price Number]]*Table1[[#This Row],[Order Quantity]])-Table1[[#This Row],[Discount $ Number]]+Table1[[#This Row],[Shipping Cost Number]] -> 57.85 | AF1423: =Table1[[#This Row],[Retail Price Number]]*Table1[[#This Row],[Order Quantity]]-Table1[[#This Row],[Discount $ Number]] -> 57.1 | AG1423: =(Table1[[#This Row],[Retail Price Number]]*Table1[[#This Row],[Order Quantity]])-Table1[[#This Row],[Discount $ Number]]-Table1[[#This Row],[Shipping Cost Number]] -> 56.35 | AH1423: =Table1[[#This Row],[Retail Price Number]]*Table1[[#This Row],[Order Quantity]] -> 65.16 | AI1423: =YEAR(Table1[[#This Row],[Order Date]]) -> 2015
A1424: 5430-1 | B1424: 41695 | C1424: Patrick Junes | D1424: Hoyts Entertainment Quarter 122 Lang Road,Moore Parra | E1424: Sydney | F1424: NSW | G1424: Home Office | H1424: Tina Carlton | I1424: Not Specified | J1424: Steady Major Accent Highlighters | K1424: Office Supplies | L1424: Small Box | M1424: Regular Air | N1424: 41697 | O1424: $3.75 | P1424: $7.08 | Q1424: $3.33 | R1424: 44 | S1424: $220.44 | T1424: 0.02 | U1424: $6.61 | V1424: $213.83 | W1424: $2.35 | X1424: $215.33 | Y1424: =VALUE(SUBSTITUTE(Table1[[#This Row],[Order Total]],"$","")) -> 213.83 | Z1424: =VALUE(SUBSTITUTE(Table1[[#This Row],[Total]],"$","")) -> 215.33 | AA1424: =Table1[[#This Row],[Order Total Number]]-Table1[[#This Row],[Total Number]] -> -1.5 | AB1424: =VALUE(SUBSTITUTE(Table1[[#This Row],[Shipping Cost]],"$","")) -> 2.35 | AC1424: =VALUE(SUBSTITUTE(Table1[[#This Row],[Discount $]],"$","")) -> 6.61 | AD1424: =VALUE(SUBSTITUTE(Table1[[#This Row],[Retail Price]],"$","")) -> 7.08 | AE1424: =(Table1[[#This Row],[Retail Price Number]]*Table1[[#This Row],[Order Quantity]])-Table1[[#This Row],[Discount $ Number]]+Table1[[#This Row],[Shipping Cost Number]] -> 307.26 | AF1424: =Table1[[#This Row],[Retail Price Number]]*Table1[[#This Row],[Order Quantity]]-Table1[[#This Row],[Discount $ Number]] -> 304.91 | AG1424: =(Table1[[#This Row],[Retail Price Number]]*Table1[[#This Row],[Order Quantity]])-Table1[[#This Row],[Discount $ Number]]-Table1[[#This Row],[Shipping Cost Number]] -> 302.56 | AH1424: =Table1[[#This Row],[Retail Price Number]]*Table1[[#This Row],[Order Quantity]] -> 311.52 | AI1424: =YEAR(Table1[[#This Row],[Order Date]]) -> 2014
A1425: 5430-1 | B1425: 41695 | C1425: Gary Hwang | D1425: 60 York St,Sydney | E1425: Sydney | F1425: NSW | G1425: Consumer | H1425: Charlie Bui | I1425: Critical | J1425: Security-Tint Envelopes | K1425: Office Supplies | L1425: Small Box | M1425: Regular Air | N1425: 41697 | O1425: $4.89 | P1425: $7.64 | Q1425: $2.75 | R1425: 34 | S1425: $220.44 | T1425: 0.03 | U1425: $6.61 | V1425: $213.83 | W1425: $1.39 | X1425: $215.33 | Y1425: =VALUE(SUBSTITUTE(Table1[[#This Row],[Order Total]],"$","")) -> 213.83 | Z1425: =VALUE(SUBSTITUTE(Table1[[#This Row],[Total]],"$","")) -> 215.33 | AA1425: =Table1[[#This Row],[Order Total Number]]-Table1[[#This Row],[Total Number]] -> -1.5 | AB1425: =VALUE(SUBSTITUTE(Table1[[#This Row],[Shipping Cost]],"$","")) -> 1.39 | AC1425: =VALUE(SUBSTITUTE(Table1[[#This Row],[Discount $]],"$","")) -> 6.61 | AD1425: =VALUE(SUBSTITUTE(Table1[[#This Row],[Retail Price]],"$","")) -> 7.64 | AE1425: =(Table1[[#This Row],[Retail Price Number]]*Table1[[#This Row],[Order Quantity]])-Table1[[#This Row],[Discount $ Number]]+Table1[[#This Row],[Shipping Cost Number]] -> 254.54 | AF1425: =Table1[[#This Row],[Retail Price Number]]*Table1[[#This Row],[Order Quantity]]-Table1[[#This Row],[Discount $ Number]] -> 253.15 | AG1425: =(Table1[[#This Row],[Retail Price Number]]*Table1[[#This Row],[Order Quantity]])-Table1[[#This Row],[Discount $ Number]]-Table1[[#This Row],[Shipping Cost Number]] -> 251.76 | AH1425: =Table1[[#This Row],[Retail Price Number]]*Table1[[#This Row],[Order Quantity]] -> 259.76 | AI1425: =YEAR(Table1[[#This Row],[Order Date]]) -> 2014
